<?xml version="1.0" ?>
<robot name = "little_car">
	<link name = "base_link">
	<!-- 在此处搭一个小车模型，
			重心离地0.05,
			视图为一个0.3×0.2×0.1的蓝色长方体，
			碰撞箱为0.21×0.3×0.11
			质量为10 -->
	<visual>
		<geometry>
			<box size="0.3 0.2 0.1"/>
		</geometry>
		<material name="blue">
			<color rgba="0 0 1 1"/>
		</material>
	</visual>
	<collision>
		<geometry>
			<box size="0.21 0.3 0.1"/>
		</geometry>
	</collision>
	<inertial>
    	<mass value="10"/>
    	<origin xyz="0 0 0.05"/>
    	<inertia ixx="0" ixy="0" ixz="0" iyy="0" iyz="0" izz="0"/>
	</inertial>
		
	</link>

	<!-- front wheel -->
	<link name="wheel_1" > 
		
		<!-- 在此处搭一个轮子，
			视图为一个0.05长，0.05半径的圆柱体，
			碰撞箱同上
			质量为10 -->
		<visual>
			<geometry>
				<cylinder radius="0.05" length="0.05"/>
			</geometry>
			<material name="blue">
				<color rgba="0 0 1 1"/>
			</material>
		</visual>
		<collision>
			<geometry>
				<cylinder radius="0.05" length="0.05"/>
			</geometry>
		</collision>
		<inertial>
			<mass value="10"/>
			<origin xyz="0.15 0.15 0"/>
			<inertia ixx="0" ixy="0" ixz="0" iyy="0" iyz="0" izz="0"/>
		</inertial>
	</link>

	<link name="wheel_2" >
		<!--   同上一个轮子  -->
		<visual>
			<geometry>
				<cylinder radius="0.05" length="0.05"/>
			</geometry>
		</visual>
		<collision>
			<geometry>
				<cylinder radius="0.05" length="0.05"/>
			</geometry>
		</collision>
		<inertial>
			<mass value="10"/>
			<inertia ixx="0" ixy="0" ixz="0" iyy="0" iyz="0" izz="0"/>
		</inertial>
	</link>


	<link name="wheel_3" >
		<!--   同上一个轮子  -->
		<visual>
			<geometry>
				<cylinder radius="0.05" length="0.05"/>
			</geometry>
		</visual>
		<collision>
			<geometry>
				<cylinder radius="0.05" length="0.05"/>
			</geometry>
		</collision>
		<inertial>
			<mass value="10"/>
			<inertia ixx="0" ixy="0" ixz="0" iyy="0" iyz="0" izz="0"/>
		</inertial>
	</link>


	<link name="wheel_4" >
		<!--   同上一个轮子  -->
		<visual>
			<geometry>
				<cylinder radius="0.05" length="0.05"/>
			</geometry>
		</visual>
		<collision>
			<geometry>
				<cylinder radius="0.05" length="0.05"/>
			</geometry>
		</collision>
		<inertial>
			<mass value="10"/>
			<inertia ixx="0" ixy="0" ixz="0" iyy="0" iyz="0" izz="0"/>>
		</inertial>
	</link>

	<joint name="base_to_wheel_1" type="continuous">
		<!--在此处填入四个性质，下面三个轮子同理，注意分别链接在不同位置
		<parent               >
		<child                >
		<axis                 >
		<origin               >

		tips:转轴定为z轴（初始圆柱体正立放置）
			origin的xyz偏移按照上面的箱子计算得出，rpy绕y轴转90度（urdf中为弧度制）
			-->
		<parent link="base_link"/>
		<child link="wheel_1"/>
		<axis xyz="0 0 1"/>
		<origin xyz="0.15 -0.15 0"rpy="0 1.5780 0"/>		
		<joint_properties damping="20.0" friction="20.0"/>
	</joint>

	<joint name="base_to_wheel_2" type="continuous">
		<parent link="base_link"/>
		<child link="wheel_2"/>
		<axis xyz="0 0 1"/>
		<origin xyz="0.15 0.15 0"rpy="0 1.5780 0"/>
		<joint_properties damping="20.0" friction="20.0"/>
	</joint>


	<joint name="base_to_wheel_3" type="continuous">
		<parent link="base_link"/>
		<child link="wheel_3"/>
		<axis xyz="0 0 1"/>
		<origin xyz="-0.15 -0.15 0"rpy="0 1.5780 0"/>
		<joint_properties damping="20.0" friction="20.0"/>
	</joint>


	<joint name="base_to_wheel_4" type="continuous">
		<parent link="base_link"/>
		<child link="wheel_4"/>
		<axis xyz="0 0 1"/>
		<origin xyz="-0.15 0.15 0"rpy="0 1.5780 0"/>
		<joint_properties damping="20.0" friction="20.0"/>
	</joint>
</robot>
