<?xml version="1.0" ?>
<robot name = "little_car">
	<link name = "base_link">
	<!-- 在此处搭一个小车模型，
			重心离地0.05,
			视图为一个0.3×0.2×0.1的蓝色长方体，
			碰撞箱为0.21×0.3×0.11
			质量为10 -->
        <!--可视化标签-->
        <visual>
           <!--1.形状-->
           <geometry>
           <box size="0.3 0.2 0.1" />
           </geometry>
            <!--2.偏移量和倾斜弧度-->
            <origin xyz="0 0 0" rpy="0 0 1.57075" />
             <!--3.颜色-->
             <material name="car_color">
                <color rgba="0 0 1 1" />
                 <!--rgb红绿蓝三原色 a透明度 取值范围都是0-1-->
             </material>
        </visual>
	<!--惯性属性-->
	<inertial>
	    <!--设置质量-->
	    <mass value="10"/>
	    <!--设置重心-->
	    <origin xyz="0 0 0.05" rpy="0 0 0"/>
	     <inertia ixx="100"  ixy="0"  ixz="0" iyy="100" iyz="0"   izz="100" />
	</inertial>
	<collision>
        <origin xyz="0 0 0" rpy="0 0 0"/>
           <geometry>
               <!--设置碰撞箱-->
              <box size="0.21 0.3 0.11" />
           </geometry>
        </collision>
	</link>

	<!-- front wheel -->
	<link name="wheel_1" > 
		
		<!-- 在此处搭一个轮子，
			视图为一个0.05长，0.05半径的圆柱体，
			碰撞箱同上
			质量为10 -->
		<visual>
                 <geometry>
                  <cylinder radius="0.05" length="0.05" />
                 </geometry>
                 <material name="wheel01">
                 <color rgba="0 0 0 1"/>
                 </material>
                </visual>
              <collision>
              <origin xyz="0 0 0" rpy="0 0 0"/>
              <geometry>
               <!--设置碰撞箱-->
              <box size="0.21 0.3 0.11" />
              </geometry>
              </collision>
              <inertial>
	    <!--设置质量-->
	    <mass value="10"/>
	     <inertia ixx="100"  ixy="0"  ixz="0" iyy="100" iyz="0" izz="100" />
	    </inertial>
	</link>

	<link name="wheel_2" >
		<visual>
                 <geometry>
                  <cylinder radius="0.05" length="0.05" />
                 </geometry>
                 <material name="wheel02">
                 <color rgba="0 0 0 1"/>
                 </material>
                </visual>
              <collision>
              <origin xyz="0 0 0" rpy="0 0 0"/>
              <geometry>
               <!--设置碰撞箱-->
              <box size="0.21 0.3 0.11" />
              </geometry>
              </collision>
              <inertial>
	    <!--设置质量-->
	    <mass value="10"/>
	     <inertia ixx="100"  ixy="0"  ixz="0" iyy="100" iyz="0" izz="100" />
	    </inertial>
	</link>


	<link name="wheel_3" >
		<visual>
                 <geometry>
                  <cylinder radius="0.05" length="0.05" />
                 </geometry>
                 <material name="wheel03">
                 <color rgba="0 0 0 1"/>
                 </material>
                </visual>
              <collision>
              <origin xyz="0 0 0" rpy="0 0 0"/>
              <geometry>
               <!--设置碰撞箱-->
              <box size="0.21 0.3 0.11" />
              </geometry>
              </collision>
              <inertial>
	    <!--设置质量-->
	    <mass value="10"/>
	     <inertia ixx="100"  ixy="0"  ixz="0" iyy="100" iyz="0" izz="100" />
	    </inertial>
	</link>


	<link name="wheel_4" >
		<!--   同上一个轮子  -->
		<visual>
                 <geometry>
                  <cylinder radius="0.05" length="0.05" />
                 </geometry>
                 <material name="wheel04">
                 <color rgba="0 0 0 1"/>
                 </material>
                </visual>
              <collision>
              <origin xyz="0 0 0" rpy="0 0 0"/>
              <geometry>
               <!--设置碰撞箱-->
              <box size="0.21 0.3 0.11" />
              </geometry>
              </collision>
              <inertial>
	    <!--设置质量-->
	    <mass value="10"/>
	     <inertia ixx="100"  ixy="0"  ixz="0" iyy="100" iyz="0" izz="100" />
	    </inertial>
	</link>

	<joint name="base_to_wheel_1" type="continuous">
		<!--在此处填入四个性质，下面三个轮子同理，注意分别链接在不同位置
		<parent               >
		<child                >
		<axis                 >
		<origin               >

		tips:转轴定为z轴（初始圆柱体正立放置）
			origin的xyz偏移按照上面的箱子计算得出，rpy绕y轴转90度（urdf中为弧度制）
			-->
		<!--链接到车体上-->
		<parent link="base_link"/>              
		<child link="wheel_1"/>
		<!--设置旋转轴为z轴-->
		<axis xyz="0 0 1"/> 
		<origin rpy="0 1.57075 0" xyz="0.15 0.1 -0.05"/>  <!--绕着y轴旋转90度 -->

		<joint_properties damping="20.0" friction="20.0"/>
	</joint>

	<joint name="base_to_wheel_2" type="continuous">
	    <!--链接到车体上-->
		<parent link="base_link"/>              
		<child link="wheel_2"/>
		<!--设置旋转轴为z轴-->
		<axis xyz="0 0 1"/> 
		<origin rpy="0 1.57075 0" xyz="0.15 -0.1 -0.05"/>  <!--绕着y轴旋转90度 -->
		<joint_properties damping="20.0" friction="20.0"/>
	</joint>


	<joint name="base_to_wheel_3" type="continuous">
		<!--链接到车体上-->
		<parent link="base_link"/>              
		<child link="wheel_3"/>
		<!--设置旋转轴为z轴-->
		<axis xyz="0 0 1"/> 
		<origin rpy="0 1.57075 0" xyz="-0.15 0.1 -0.05"/>  <!--绕着y轴旋转90度 -->
		<joint_properties damping="20.0" friction="20.0"/>
	</joint>


	<joint name="base_to_wheel_4" type="continuous">
				<!--链接到车体上-->
		<parent link="base_link"/>              
		<child link="wheel_4"/>
		<!--设置旋转轴为z轴-->
		<axis xyz="0 0 1"/> 
		<origin rpy="0 1.57075 0" xyz="-0.15 -0.1 -0.05"/>  <!--绕着y轴旋转90度 -->
		<joint_properties damping="20.0" friction="20.0"/>
	</joint>
</robot>
