<?xml version="1.0" ?>

<robot name = "little_car">
	<link name = "base_link">
		<visual>
			<geometry>
				<box size="0.3 0.2 0.1"/>
			</geometry>
			<material name="blue">
				<color rgba="0 0 1 1"/>
			</material>
			<origin xyz="0 0 0" rpy="0 0 0">
			</origin>
		</visual>

		<collision>
			<geometry>
				<box size="0.21 0.3 0.11"/>
			</geometry>
		</collision>

		<inertial>
			<mass value="10"/>
			<inertia ixx="100"  ixy="0"  ixz="0" iyy="100" iyz="0" izz="100"/>
		</inertial>


	</link>


	<link name="wheel_1" > 
		<visual>
			<geometry>
				<cylinder radius="0.05" length="0.05" />
			</geometry>
		
			<material name="blue">
				<color rgba="1 1 1 1"/>
			</material>
		</visual>
		<collision>
			<geometry>
				<cylinder radius="0.05" length="0.05" />
			</geometry>
		</collision>
		<inertial>
			<mass value="10"/>
			<inertia ixx="100"  ixy="0"  ixz="0" iyy="100" iyz="0" izz="100"/>
		</inertial>
		
	</link>

	<link name="wheel_2" >
	
		<visual>
			<geometry>
				<cylinder radius="0.05" length="0.05" />
			</geometry>
		
			<material name="blue">
				<color rgba="1 1 1 1"/>
			</material>
		</visual>
		<collision>
			<geometry>
				<cylinder radius="0.05" length="0.05" />
			</geometry>
		</collision>
		<inertial>
			<mass value="10"/>
			<inertia ixx="100"  ixy="0"  ixz="0" iyy="100" iyz="0" izz="100"/>
		</inertial>
	</link>


	<link name="wheel_3" >
	
		<visual>
			<geometry>
				<cylinder radius="0.05" length="0.05" />
			</geometry>
		
			<material name="blue">
				<color rgba="1 1 1 1"/>
			</material>
		</visual>
		<collision>
			<geometry>
				<cylinder radius="0.05" length="0.05" />
			</geometry>
		</collision>
		<inertial>
			<mass value="10"/>
			<inertia ixx="100"  ixy="0"  ixz="0" iyy="100" iyz="0" izz="100"/>
		</inertial>
	</link>


	<link name="wheel_4" >
		<visual>
			<geometry>
				<cylinder radius="0.05" length="0.05" />
			</geometry>
		
			<material name="blue">
				<color rgba="1 1 1 1"/>
			</material>
		</visual>
		<collision>
			<geometry>
				<cylinder radius="0.05" length="0.05" />
			</geometry>
		</collision>
		<inertial>
			<mass value="10"/>
			<inertia ixx="100"  ixy="0"  ixz="0" iyy="100" iyz="0" izz="100"/>
		</inertial>
	</link>


	<joint name="base_to_wheel_1" type="continuous">	
		<parent link="base_link"/>
		<child link="wheel_1"/>
		<origin xyz="0.12 0.125 -0.025" rpy="1.57 0 0"/>
		<joint_properties damping="20.0" friction="20.0"/>
	</joint>

	<joint name="base_to_wheel_2" type="continuous">		
        <parent link="base_link"/>
		<child link="wheel_2"/>
		<origin xyz="0.12 -0.125 -0.025" rpy="1.57 0 0"/>
		<joint_properties damping="20.0" friction="20.0"/>
	</joint>


	<joint name="base_to_wheel_3" type="continuous">	
        <parent link="base_link"/>
		<child link="wheel_3"/>
		<origin xyz="-0.12 -0.125 -0.025" rpy="1.57 0 0"/>
		<joint_properties damping="20.0" friction="20.0"/>
	</joint>


	<joint name="base_to_wheel_4" type="continuous">
		<parent link="base_link"/>
		<child link="wheel_4"/>
		<origin xyz="-0.12 0.125 -0.025" rpy="1.57 0 0"/>
		<joint_properties damping="20.0" friction="20.0"/>
	</joint>

</robot>
