<?xml version="1.0"?>
	<robot name="little_car">
		<link name="base_link">	
			<inertial>
				<origin xyz="0 0 0.05" rpy="0 0 0"/>   
           			<mass value="10"/>                 
            			<inertia ixx="0" ixy="0" ixz="0" iyy="0" iyz="0" izz="0" />  
        		</inertial>

			<visual>
				<geometry>
					<box size="0.3 0.2 0.1"/>
				</geometry>
				<origin xyz="0 0 0.05" rpy="0 0 0"/>
				<material name="blue">
					<color rgba="0 0 1 1"/>
				</material>
			</visual>
			<collision>
				<geometry>
		  		  <box size="0.21 0.3 0.11"/>
				</geometry>
	    		</collision>
		</link>
		
		<link name="wheel_1">	
			<inertial>
				<origin xyz="0 0 0.05" rpy="0 0 0"/>   
           			<mass value="10"/>                 
            			<inertia ixx="0" ixy="0" ixz="0" iyy="0" iyz="0" izz="0" />  
        		</inertial>			
			<visual>
				<geometry>
					<cylinder length="0.05" radius="0.05"/>
				</geometry>
				<origin rpy="0 1.5 0" xyz="0.1 0.1 0"/> 
				<material name="black">
					<color rgba="0 0 0 1"/>
				</material>
			</visual>
	    		<collision>
				<geometry>
		    			<box size="0.21 0.3 0.11"/>
				</geometry>
	    		</collision>
		</link>
		
		<link name="wheel_2">
			<inertial>
				<origin xyz="0 0 0.05" rpy="0 0 0"/>   
           			<mass value="10"/>                 
            			<inertia ixx="0" ixy="0" ixz="0" iyy="0" iyz="0" izz="0" />  
        		</inertial>
	
			<visual>
				<geometry>
					<cylinder length="0.05" radius="0.05"/>
				</geometry>
				<origin rpy="0 1.5 0" xyz="-0.1 0.1 0"/>
				<material name="black">
					<color rgba="0 0 0 1"/>
				</material>
			</visual>
	    		<collision>
				<geometry>
		    			<box size="0.21 0.3 0.11"/>
				</geometry>
	    		</collision>
		</link>
		
		<link name="wheel_3">	
			<inertial>
				<origin xyz="0 0 0.05" rpy="0 0 0"/>   
           			<mass value="10"/>                 
            			<inertia ixx="0" ixy="0" ixz="0" iyy="0" iyz="0" izz="0" />  
        		</inertial>	
			<visual>
				<geometry>
					<cylinder length="0.05" radius="0.05"/>
				</geometry>
				<origin rpy="0 1.5 0" xyz="0.1 -0.1 0"/>
				<material name="black">
					<color rgba="0 0 0 1"/>
				</material>
			</visual>
	    		<collision>
				<geometry>
		    			<box size="0.21 0.3 0.11"/>
				</geometry>
	    		</collision>
		</link>
		
		<link name="wheel_4">
			<inertial>
				<origin xyz="0 0 0.05" rpy="0 0 0"/>   
           			<mass value="10"/>                 
            			<inertia ixx="0" ixy="0" ixz="0" iyy="0" iyz="0" izz="0" />  
        		</inertial>
			<visual>
				<geometry>
					<cylinder length="0.05" radius="0.05"/>
				</geometry>
				<origin rpy="0 1.5 0" xyz="-0.1 -0.1 0"/>
				<material name="black">
					<color rgba="0 0 0 1"/>
				</material>
			</visual>
	    		<collision>
				<geometry>
		    			<box size="0.21 0.3 0.11"/>
				</geometry>
	    		</collision>
		</link>
		<joint name="base_to_wheel1" type="continuous">
			<parent link="base_link"/>
			<child link="wheel_1"/>
			<joint_properties damping="20.0" friction="20.0"/>
		</joint>
		
		<joint name="base_to_wheel2" type="continuous">
			<parent link="base_link"/>
			<child link="wheel_2"/>
			<joint_properties damping="20.0" friction="20.0"/>
		</joint>
		
		<joint name="base_to_wheel3" type="continuous">
			<parent link="base_link"/>
			<child link="wheel_3"/>
			<joint_properties damping="20.0" friction="20.0"/>
		</joint>
		
		<joint name="base_to_wheel4" type="continuous">
			<parent link="base_link"/>
			<child link="wheel_4"/>
			<joint_properties damping="20.0" friction="20.0"/>
		</joint>
	</robot>

